Friday September 27th 2013 10:02 am -04:00,Hi mateI get all result correct in the function of assignment but I run a3_driver and get this error: Traceback (most recent call last):  File /home/erl/miPython/a3_driver.py line 88 in <module>    words = a3.read_words(words_file)  File /home/erl/miPython/a3.py line 199 in read_words    file = open(words_file r)TypeError: invalid file: <_io.TextIOWrapper name=/home/erl/miPython/a3_driver.py mode=r encoding=UTF-8>thanks for you help me., Unresolved,1
Saturday September 28th 2013 6:06 am -04:00,Thanks very much to all I have managed to solve it ;), Unresolved,0
Friday September 27th 2013 10:24 am -04:00,Hi matesThese are my results:>>> read_words(wordlist1.txt)[CRUNCHY COWS EAT GRASS]and>>> read_board(board1.txt)[[E F J A J C O W S S] [S D G K S R F D F F] [A S R J D U S K L K] [H E A N D N D J W A] [A N S D N C N E O P] [P M S N F H H E J E] [J E P Q L Y N X D L]]these are the summary of my errors when I submit:thanks for you help me :), Unresolved,0
Saturday September 28th 2013 6:06 am -04:00,Thanks very much to all I have managed to solve it ;), Unresolved,0
