Monday September 2nd 2013 10:09 pm -04:00,Hello I received one test failure for my Assignment 1 submission.  The test test_get_hours.TestGetHours.test_large_input failed with Assertion Error: 9 != 105.  I was able to run the method using a large number and get the result of 105.  The method I created was:def get_hours(seconds):        (int) -> int    Return the hours part of the time given in seconds.    >>> get_hours(3800)    1    >>> get_hours(8652)    2    >>> get_hours(500)    0        return seconds // 60 // 60If I run get_hours(379200) in the python shell I do get 105.  Could you please let me know why the test failed?, Unresolved,1
