Wednesday September 18th 2013 4:18 pm -04:00,hii fareez im having difficulty with the sum of the range.when i try this sum(range(1234102053))print(sum)i get thisTraceback (most recent call last):  File /home/obiamaka/try.py line 1 in <module>    sum(range(1234102053))TypeError: int object is not callableplease what am i doing wrong, Unresolved,0
Wednesday September 18th 2013 5:20 pm -04:00,still getting thisTraceback (most recent call last):  File <pyshell#12> line 1 in <module>    sum(range(1400))TypeError: int object is not callablewhen i try  sum(range(1400)), Unresolved,0
