Sunday September 29th 2013 8:17 am -04:00,Report was generated in: 12:08:01 - 29/09/2013Summary: Test results statistics - All=11; Errors=11; Failures=0; Successes=0; Warnings=0. Duration: 0:00:00 [H:M:S].Description: Table is grouped by: {{group}} Sorting order is determined by: {{priority}} {{group}} {{test_module_name}} {{test_class_name}} {{test_method_name}}Mid-summary is determined by: {{test_module_name}}Show Summary Mid-Summaries Failed AllGroupAllPassFailErrorWarningViewstudent1100110DetailSummary: test_a3 (student)1100110student: test_a3.Test_02_ReadBoard.runERRORstudent: test_a3.Test_11_NumWordsOnBoard.runERRORstudent: test_a3.Test_04_MakeStrFromRow.runERRORstudent: test_a3.Test_09_WordScore.runERRORstudent: test_a3.Test_10_UpdateScore.runERRORstudent: test_a3.Test_08_BoardContainsWord.runERRORstudent: test_a3.Test_06_MakeStrFromColumn.runERRORstudent: test_a3.Test_01_ReadWords.runERRORstudent: test_a3.Test_07_BoardContainsWordInColumn.runERRORstudent: test_a3.Test_03_IsValidWord.runERRORstudent: test_a3.Test_05_BoardContainsWordInRow.runERRORTotal1100110I get this error despite the game running fine, Unresolved,0
Sunday September 29th 2013 1:04 am -04:00,Traceback (most recent call last):  File C:\Python33\a3_driver.py line 88 in <module>    words = a3.read_words(words_file)  File C:\Python33\a3.py line 216 in read_words    file = open(words_filer)TypeError: invalid file: <_io.TextIOWrapper name=C:/Python33/a3.py mode=r encoding=cp1252> I get this error on running the driver file any solution for this, Resolved,0
Sunday September 29th 2013 8:22 am -04:00,Thanks tom , Resolved,0
Friday October 4th 2013 1:30 am -04:00,Use strip function to strip the space after each line, Resolved,0
